Workbook

Sheet Read me
B1: Sixfold: expenses and profit
B2: Built 21 Oct 2026. Covers Sixfold and 365 Aeration & Seeding together; each job and payment is tagged with which one.
B4: How to read the colours
B5: Yellow cell: only you know this. Type the number in. Totals and profit update on their own.
A6: x | B6: Blue text: a number I put in from a record (Square, the app, the Spend Ledger, a receipt). Hover the cell for where it came from.
B7: Black text: a formula. Leave these alone.
B9: The tabs
B10: Profit: money in, per-job costs, set costs, ads and net profit by month (Aug, Sep, Oct 2026), each business to date, and one week (pick the Monday).
B11: Fixed costs: websites, software, storage, the truck, the aerator, the trailer card, insurance and ads. Monthly, weekly and yearly side by side.
B12: Variable per job: every job with its seed, fertilizer, gas, card fees and the 20% employee cost, and what the job made.
B13: Employees: pay not tied to a job (hourly or salary). The crew on each job is the 20% employee cost on the Variable per job tab.
B14: Payments: every Square payment on both locations (365Aeration and Six Fold Colorado), with Square's fee.
B16: Where the numbers came from
B17: Websites, domains, hosting, Google Workspace: the Spend Ledger (the expenses tracker artifact, entries tagged Sixfold and 365).
B18: Jobs, prices, crew, seed and fertilizer recorded: the Sixfold app, read on 21 Oct 2026.
B19: Payments and card fees: Square, both locations, read on 21 Oct 2026. Square charged its fee on each card payment; those are the real fees, not a percentage.
B20: Seed price: SiteOne Englewood invoice 24 Jul 2026, 6 x 50 lb LESCO Tuf-Turf for $773.34 with tax ($128.89 a bag).
... B44: Surge and Traverse costs from the Spend Ledger (Claude, surgeftw.com, the Traverse server) are not Sixfold's and are not here.

Sheet Profit
A1: Sixfold profit
A2: Money in is when Square took it. Job costs are in the month of the job (Done jobs only). October runs to the 21st. Yellow = still to fill in; until then those costs count as $0, so profit reads high.
B4: Aug 2026 | C4: Sep 2026 | D4: Oct 2026 | E4: Total | F4: Where from
A5: month key (do not edit) | B5: 2026-08 | C5: 2026-09 | D5: 2026-10
A7: Money in
A8: Payments received (after refunds) | B8: =SUMIFS(Payments!$I$5:$I$26,Payments!$B$5:$B$26,B$5) | C8: =SUMIFS(Payments!$I$5:$I$26,Payments!$B$5:$B$26,C$5) | D8: =SUMIFS(Payments!$I$5:$I$26,Payments!$B$5:$B$26,D$5) | E8: =SUM(B8:D8) | F8: Payments tab
A9: Square fees | B9: =SUMIFS(Payments!$H$5:$H$26,Payments!$B$5:$B$26,B$5) | C9: =SUMIFS(Payments!$H$5:$H$26,Payments!$B$5:$B$26,C$5) | D9: =SUMIFS(Payments!$H$5:$H$26,Payments!$B$5:$B$26,D$5) | E9: =SUM(B9:D9) | F9: Payments tab: the fee Square took on each card payment
A10: Money in after fees | B10: =B8-B9 | C10: =C8-C9 | D10: =D8-D9 | E10: =SUM(B10:D10)
A12: Per-job costs (Done jobs)
A13: Seed | B13: =SUMIFS('Variable per job'!$N$16:$N$34,'Variable per job'!$AB$16:$AB$34,B$5,'Variable per job'!$E$16:$E$34,"Done") | C13: =SUMIFS('Variable per job'!$N$16:$N$34,'Variable per job'!$AB$16:$AB$34,C$5,'Variable per job'!$E$16:$E$34,"Done") | D13: =SUMIFS('Variable per job'!$N$16:$N$34,'Variable per job'!$AB$16:$AB$34,D$5,'Variable per job'!$E$16:$E$34,"Done") | E13: =SUM(B13:D13) | F13: Variable per job
A14: Fertilizer | B14: =SUMIFS('Variable per job'!$Q$16:$Q$34,'Variable per job'!$AB$16:$AB$34,B$5,'Variable per job'!$E$16:$E$34,"Done") | C14: =SUMIFS('Variable per job'!$Q$16:$Q$34,'Variable per job'!$AB$16:$AB$34,C$5,'Variable per job'!$E$16:$E$34,"Done") | D14: =SUMIFS('Variable per job'!$Q$16:$Q$34,'Variable per job'!$AB$16:$AB$34,D$5,'Variable per job'!$E$16:$E$34,"Done") | E14: =SUM(B14:D14) | F14: Variable per job
A15: Gas (truck + aerator) | B15: =SUMIFS('Variable per job'!$S$16:$S$34,'Variable per job'!$AB$16:$AB$34,B$5,'Variable per job'!$E$16:$E$34,"Done")+SUMIFS('Variable per job'!$AC$16:$AC$34,'Variable per job'!$AB$16:$AB$34,B$5,'Variable per job'!$E$16:$E$34,"Done") | C15: =SUMIFS('Variable per job'!$S$16:$S$34,'Variable per job'!$AB$16:$AB$34,C$5,'Variable per job'!$E$16:$E$34,"Done")+SUMIFS('Variable per job'!$AC$16:$AC$34,'Variable per job'!$AB$16:$AB$34,C$5,'Variable per job'!$E$16:$E$34,"Done") | D15: =SUMIFS('Variable per job'!$S$16:$S$34,'Variable per job'!$AB$16:$AB$34,D$5,'Variable per job'!$E$16:$E$34,"Done")+SUMIFS('Variable per job'!$AC$16:$AC$34,'Variable per job'!$AB$16:$AB$34,D$5,'Variable per job'!$E$16:$E$34,"Done") | E15: =SUM(B15:D15) | F15: Variable per job (estimate from miles unless overridden)
A16: Other materials | B16: =SUMIFS('Variable per job'!$V$16:$V$34,'Variable per job'!$AB$16:$AB$34,B$5,'Variable per job'!$E$16:$E$34,"Done") | C16: =SUMIFS('Variable per job'!$V$16:$V$34,'Variable per job'!$AB$16:$AB$34,C$5,'Variable per job'!$E$16:$E$34,"Done") | D16: =SUMIFS('Variable per job'!$V$16:$V$34,'Variable per job'!$AB$16:$AB$34,D$5,'Variable per job'!$E$16:$E$34,"Done") | E16: =SUM(B16:D16) | F16: Variable per job
A17: Employee cost (20% of each job) | B17: =SUMIFS('Variable per job'!$X$16:$X$34,'Variable per job'!$AB$16:$AB$34,B$5,'Variable per job'!$E$16:$E$34,"Done") | C17: =SUMIFS('Variable per job'!$X$16:$X$34,'Variable per job'!$AB$16:$AB$34,C$5,'Variable per job'!$E$16:$E$34,"Done") | D17: =SUMIFS('Variable per job'!$X$16:$X$34,'Variable per job'!$AB$16:$AB$34,D$5,'Variable per job'!$E$16:$E$34,"Done") | E17: =SUM(B17:D17) | F17: Variable per job: 20% of each job's price
A18: Per-job costs | B18: =SUM(B13:B17) | C18: =SUM(C13:C17) | D18: =SUM(D13:D17) | E18: =SUM(B18:D18)
A20: Running costs
A21: Ad spend (Meta) | D21: ='Fixed costs'!$G$26 | E21: =SUM(B21:D21) | F21: October: $6,066 a month (Fixed costs tab). Aug and Sep: fill in if ads ran.
A22: Count set costs this month? (1 yes, 0 no) | B22: 1 | C22: 1 | D22: 1 | F22: Set a month to 0 if the business was not paying these yet.
A23: Set costs (truck, storage, aerator, card, software) | B23: =('Fixed costs'!$G$31-'Fixed costs'!$G$26)*B22 | C23: =('Fixed costs'!$G$31-'Fixed costs'!$G$26)*C22 | D23: =('Fixed costs'!$G$31-'Fixed costs'!$G$26)*D22 | E23: =SUM(B23:D23) | F23: Fixed costs tab: monthly total without ads
A24: Pay not tied to a job (hourly, salary) | B24: =Employees!$G$12*B22 | C24: =Employees!$G$12*C22 | D24: =Employees!$G$12*D22 | E24: =SUM(B24:D24) | F24: Employees tab
A25: One-off purchases | B25: =SUMIFS('Fixed costs'!$C$36:$C$41,'Fixed costs'!$D$36:$D$41,B$5) | C25: =SUMIFS('Fixed costs'!$C$36:$C$41,'Fixed costs'!$D$36:$D$41,C$5) | D25: =SUMIFS('Fixed costs'!$C$36:$C$41,'Fixed costs'!$D$36:$D$41,D$5) | E25: =SUM(B25:D25) | F25: Fixed costs tab, one-off purchases table
A26: Running costs | B26: =SUM(B21,B23:B25) | C26: =SUM(C21,C23:C25) | D26: =SUM(D21,D23:D25) | E26: =SUM(E21,E23:E25)
A28: Net profit | B28: =B10-B18-B26 | C28: =C10-C18-C26 | D28: =D10-D18-D26 | E28: =E10-E18-E26
A29: Net margin (profit / money in) | B29: =IF(B8<100,"",B28/B8) | C29: =IF(C8<100,"",C28/C8) | D29: =IF(D8<100,"",D28/D8) | E29: =IF(E8<100,"",E28/E8)
A31: Still to come in
A32: Owed on Done jobs | B32: =SUMIFS('Variable per job'!$I$16:$I$34,'Variable per job'!$E$16:$E$34,"Done") | C32: Brian S. owes $200
A33: Booked jobs: price | B33: =SUMIFS('Variable per job'!$G$16:$G$34,'Variable per job'!$E$16:$E$34,"Booked") | C33: Sreenivas (23 Oct) and Joseph (30 Oct)
A34: Booked jobs: deposits already in | B34: =SUMIFS('Variable per job'!$H$16:$H$34,'Variable per job'!$E$16:$E$34,"Booked")
A35: Booked jobs: still to collect | B35: =B33-B34
A37: Each business to date (Done jobs, before running costs)
B38: Sixfold | C38: 365 | D38: Both
A39: Jobs done | B39: =COUNTIFS('Variable per job'!$E$16:$E$34,"Done",'Variable per job'!$C$16:$C$34,"Sixfold") | C39: =COUNTIFS('Variable per job'!$E$16:$E$34,"Done",'Variable per job'!$C$16:$C$34,"365") | D39: =B39+C39
A40: Job prices | B40: =SUMIFS('Variable per job'!$G$16:$G$34,'Variable per job'!$E$16:$E$34,"Done",'Variable per job'!$C$16:$C$34,"Sixfold") | C40: =SUMIFS('Variable per job'!$G$16:$G$34,'Variable per job'!$E$16:$E$34,"Done",'Variable per job'!$C$16:$C$34,"365") | D40: =B40+C40
A41: Per-job costs (materials, gas, fees, crew) | B41: =SUMIFS('Variable per job'!$Y$16:$Y$34,'Variable per job'!$E$16:$E$34,"Done",'Variable per job'!$C$16:$C$34,"Sixfold") | C41: =SUMIFS('Variable per job'!$Y$16:$Y$34,'Variable per job'!$E$16:$E$34,"Done",'Variable per job'!$C$16:$C$34,"365") | D41: =B41+C41
A42: Job profit | B42: =B40-B41 | C42: =C40-C41 | D42: =D40-D41
A43: Margin | B43: =IF(B40=0,0,B42/B40) | C43: =IF(C40=0,0,C42/C40) | D43: =IF(D40=0,0,D42/D40)
A44: Average price per job | B44: =IF(B39=0,0,B40/B39) | C44: =IF(C39=0,0,C40/C39) | D44: =IF(D39=0,0,D40/D39)
A46: Per-job costs include the 20% employee cost. Margin is left blank in a month with under $100 in.
A48: One week
A49: Week starting (a Monday) | B49: 46307 | C49: =B49+6 | D49: Sunday
...

Sheet Fixed costs
A1: Fixed costs
A2: What Sixfold pays whether or not there is a job. Monthly cost = the bill turned into a month, times Sixfold's share; weekly = monthly x 12 / 52. Status "Planned" or "Stopped" counts as 0.
A4: Item | B4: Vendor | C4: Billed | D4: Amount per bill ($) | E4: Status | F4: Sixfold share | G4: Monthly cost ($) | H4: Weekly cost ($) | I4: Yearly cost ($) | J4: Renews / next | K4: Where the number came from
A5: Websites, software and platforms
A6: sixfoldcolorado.com domain | B6: Squarespace | C6: Yearly | D6: 20 | E6: Active | F6: 1 | G6: =IF(E6="Active",IF(C6="Monthly",N(D6),IF(C6="Quarterly",N(D6)/3,IF(C6="Yearly",N(D6)/12,0))),0)*F6 | H6: =G6*12/52 | I6: =G6*12 | J6: 2027-08-21 | K6: Spend Ledger artifact (first year was about $18)
A7: 365aeration.com domain | B7: Squarespace | C7: Yearly | D7: 20 | E7: Active | F7: 1 | G7: =IF(E7="Active",IF(C7="Monthly",N(D7),IF(C7="Quarterly",N(D7)/3,IF(C7="Yearly",N(D7)/12,0))),0)*F7 | H7: =G7*12/52 | I7: =G7*12 | J7: 2027-10-14 | K7: Spend Ledger artifact: the main 365 address
A8: aeration365.com domain | B8: Squarespace | C8: Yearly | D8: 20 | E8: Active | F8: 1 | G8: =IF(E8="Active",IF(C8="Monthly",N(D8),IF(C8="Quarterly",N(D8)/3,IF(C8="Yearly",N(D8)/12,0))),0)*F8 | H8: =G8*12/52 | I8: =G8*12 | J8: 2027-10-14 | K8: Spend Ledger artifact: kept so the mistyped address forwards; 365 email sits on it
A9: SiteGround hosting: Sixfold, 365 and Surge sites | B9: SiteGround | C9: Yearly | D9: 359.88 | E9: Active | F9: 1 | G9: =IF(E9="Active",IF(C9="Monthly",N(D9),IF(C9="Quarterly",N(D9)/3,IF(C9="Yearly",N(D9)/12,0))),0)*F9 | H9: =G9*12/52 | I9: =G9*12 | J9: 2027-09-02 | K9: Spend Ledger artifact. Hosts Surge's site too: set Sixfold's share (100% for now).
A10: Google Workspace, sixfoldcolorado.com (4 mailboxes) | B10: Google via Squarespace | C10: Monthly | D10: 33.6 | E10: Active | F10: 1 | G10: =IF(E10="Active",IF(C10="Monthly",N(D10),IF(C10="Quarterly",N(D10)/3,IF(C10="Yearly",N(D10)/12,0))),0)*F10 | H10: =G10*12/52 | I10: =G10*12 | J10: 21st | K10: Spend Ledger artifact: Starter plan
A11: Google Workspace, aeration365.com (Jen's mailbox) | B11: Google via Squarespace | C11: Monthly | D11: 8.4 | E11: Active | F11: 1 | G11: =IF(E11="Active",IF(C11="Monthly",N(D11),IF(C11="Quarterly",N(D11)/3,IF(C11="Yearly",N(D11)/12,0))),0)*F11 | H11: =G11*12/52 | I11: =G11*12 | J11: 14th | K11: Spend Ledger artifact
A12: Google Workspace seat, forms@aeration365.com (app emails) | B12: Google via Squarespace | C12: Monthly | D12: 8.4 | E12: Planned | F12: 1 | G12: =IF(E12="Active",IF(C12="Monthly",N(D12),IF(C12="Quarterly",N(D12)/3,IF(C12="Yearly",N(D12)/12,0))),0)*F12 | H12: =G12*12/52 | I12: =G12*12 | K12: Spend Ledger artifact says Planned (card declined 18 Oct). Set Active once it bills.
A13: ClickUp (Jen's lead list) | B13: ClickUp | C13: Monthly | E13: Active | F13: 1 | G13: =IF(E13="Active",IF(C13="Monthly",N(D13),IF(C13="Quarterly",N(D13)/3,IF(C13="Yearly",N(D13)/12,0))),0)*F13 | H13: =G13*12/52 | I13: =G13*12 | K13: Not in the ledger: fill in, or set Stopped if it is free.
A14: Phone line(s), incl. 365's (720) 830-4553 | C14: Monthly | E14: Active | F14: 1 | G14: =IF(E14="Active",IF(C14="Monthly",N(D14),IF(C14="Quarterly",N(D14)/3,IF(C14="Yearly",N(D14)/12,0))),0)*F14 | H14: =G14*12/52 | I14: =G14*12 | K14: Not in the ledger: fill in.
A15: Other software or subscriptions | C15: Monthly | E15: Active | F15: 1 | G15: =IF(E15="Active",IF(C15="Monthly",N(D15),IF(C15="Quarterly",N(D15)/3,IF(C15="Yearly",N(D15)/12,0))),0)*F15 | H15: =G15*12/52 | I15: =G15*12
A16: Operations
A17: Aerator | C17: Monthly | D17: 325 | E17: Active | F17: 1 | G17: =IF(E17="Active",IF(C17="Monthly",N(D17),IF(C17="Quarterly",N(D17)/3,IF(C17="Yearly",N(D17)/12,0))),0)*F17 | H17: =G17*12/52 | I17: =G17*12 | K17: Matthew, 21 Oct 2026: $325 a month for the aerator.
A18: Storage unit, 333 W Hampden Ave | C18: Monthly | D18: 414 | E18: Active | F18: 1 | G18: =IF(E18="Active",IF(C18="Monthly",N(D18),IF(C18="Quarterly",N(D18)/3,IF(C18="Yearly",N(D18)/12,0))),0)*F18 | H18: =G18*12/52 | I18: =G18*12 | K18: Matthew, 21 Oct 2026: $414 a month for storage.
A19: Credit card payment (holds the trailers) | C19: Monthly | D19: 500 | E19: Active | F19: 1 | G19: =IF(E19="Active",IF(C19="Monthly",N(D19),IF(C19="Quarterly",N(D19)/3,IF(C19="Yearly",N(D19)/12,0))),0)*F19 | H19: =G19*12/52 | I19: =G19*12 | K19: Matthew, 21 Oct 2026: $500 a month on the credit card that holds the trailers.
A20: Equipment upkeep and repairs | C20: Monthly | E20: Active | F20: 1 | G20: =IF(E20="Active",IF(C20="Monthly",N(D20),IF(C20="Quarterly",N(D20)/3,IF(C20="Yearly",N(D20)/12,0))),0)*F20 | H20: =G20*12/52 | I20: =G20*12 | K20: An average month, if you want one in.
A21: Trucks
A22: Truck | C22: Monthly | D22: 1000 | E22: Active | F22: 1 | G22: =IF(E22="Active",IF(C22="Monthly",N(D22),IF(C22="Quarterly",N(D22)/3,IF(C22="Yearly",N(D22)/12,0))),0)*F22 | H22: =G22*12/52 | I22: =G22*12 | K22: Matthew, 21 Oct 2026: truck $1,000 a month.
A23: Truck: insurance, if not in the $1,000 | C23: Monthly | E23: Active | F23: 1 | G23: =IF(E23="Active",IF(C23="Monthly",N(D23),IF(C23="Quarterly",N(D23)/3,IF(C23="Yearly",N(D23)/12,0))),0)*F23 | H23: =G23*12/52 | I23: =G23*12 | K23: Leave empty if the $1,000 already covers it.
A24: Truck: registration, if not in the $1,000 | B24: Colorado DMV | C24: Yearly | E24: Active | F24: 1 | G24: =IF(E24="Active",IF(C24="Monthly",N(D24),IF(C24="Quarterly",N(D24)/3,IF(C24="Yearly",N(D24)/12,0))),0)*F24 | H24: =G24*12/52 | I24: =G24*12
A25: Advertising
A26: Ads (Meta) | B26: Meta | C26: Monthly | D26: 6066 | E26: Active | F26: 1 | G26: =IF(E26="Active",IF(C26="Monthly",N(D26),IF(C26="Quarterly",N(D26)/3,IF(C26="Yearly",N(D26)/12,0))),0)*F26 | H26: =G26*12/52 | I26: =G26*12 | K26: Matthew, 21 Oct 2026: $6,066 a month for ads. On the Profit tab as its own line.
A27: Insurance and business
A28: Business insurance (general liability) | C28: Yearly | E28: Active | F28: 1 | G28: =IF(E28="Active",IF(C28="Monthly",N(D28),IF(C28="Quarterly",N(D28)/3,IF(C28="Yearly",N(D28)/12,0))),0)*F28 | H28: =G28*12/52 | I28: =G28*12 | K28: Fill in the premium; change Billed to Monthly if it is paid monthly.
A29: Other insurance (workers' comp, equipment) | C29: Yearly | E29: Active | F29: 1 | G29: =IF(E29="Active",IF(C29="Monthly",N(D29),IF(C29="Quarterly",N(D29)/3,IF(C29="Yearly",N(D29)/12,0))),0)*F29 | H29: =G29*12/52 | I29: =G29*12
A30: Accounting, bank fees, licences | C30: Monthly | E30: Active | F30: 1 | G30: =IF(E30="Active",IF(C30="Monthly",N(D30),IF(C30="Quarterly",N(D30)/3,IF(C30="Yearly",N(D30)/12,0))),0)*F30 | H30: =G30*12/52 | I30: =G30*12
A31: Total set costs, ads included | G31: =SUM(G6:G30) | H31: =SUM(H6:H30) | I31: =SUM(I6:I30)
A34: One-off purchases | B34: Printing, tools, signs: counted in the month bought. Seed and fertilizer are NOT entered here; they are counted per job on the Variable sheet.
A35: Item | B35: Date bought | C35: Amount ($) | D35: Month | E35: Note
A36: Business cards (printed) | D36: =IF(B36="","",TEXT(B36,"yyyy-mm")) | E36: Fill in the date and the amount.
A37: Yard signs (FedEx print) | D37: =IF(B37="","",TEXT(B37,"yyyy-mm")) | E37: Fill in when they are printed and paid for.
D38: =IF(B38="","",TEXT(B38,"yyyy-mm"))
D39: =IF(B39="","",TEXT(B39,"yyyy-mm"))
D40: =IF(B40="","",TEXT(B40,"yyyy-mm"))
D41: =IF(B41="","",TEXT(B41,"yyyy-mm"))

Sheet Employees
A1: Employees and pay
A2: The crew on each job costs 20% of the job price, set on the Variable per job tab. Use this tab only for pay NOT tied to a job: "Hourly" = rate x hours a month; "Salary (monthly)" = the month's pay; "Per job" or "Not paid" = nothing extra here.
A4: Name | B4: Role | C4: Paid how | D4: Rate | E4: Hours a month (hourly only) | F4: Extra on top (payroll tax etc.) | G4: Monthly cost, not per job ($) | H4: Note
A5: Brad McPherson | B5: Crew: did 8 of the 9 jobs in the app | F5: 0 | G5: =IF(C5="Hourly",N(D5)*N(E5),IF(C5="Salary (monthly)",N(D5),0))*(1+N(F5)) | H5: Recorded as crew on every 365 job except Carlos.
A6: Brandon Long | B6: Owner; crew on Carlos's job | C6: Not paid | F6: 0 | G6: =IF(C6="Hourly",N(D6)*N(E6),IF(C6="Salary (monthly)",N(D6),0))*(1+N(F6)) | H6: Owner pay is a draw, not a cost: leave as "Not paid" unless he takes a set amount per job.
A7: Jen McPherson | B7: Office: quotes and books 365 jobs | F7: 0 | G7: =IF(C7="Hourly",N(D7)*N(E7),IF(C7="Salary (monthly)",N(D7),0))*(1+N(F7))
A8: Nneka | B8: Office; runs a door team | F8: 0 | G8: =IF(C8="Hourly",N(D8)*N(E8),IF(C8="Salary (monthly)",N(D8),0))*(1+N(F8))
A9: Cai Silva | B9: Office | F9: 0 | G9: =IF(C9="Hourly",N(D9)*N(E9),IF(C9="Salary (monthly)",N(D9),0))*(1+N(F9))
F10: 0 | G10: =IF(C10="Hourly",N(D10)*N(E10),IF(C10="Salary (monthly)",N(D10),0))*(1+N(F10))
F11: 0 | G11: =IF(C11="Hourly",N(D11)*N(E11),IF(C11="Salary (monthly)",N(D11),0))*(1+N(F11))
A12: Total monthly pay (not per job) | G12: =SUM(G5:G11)
A14: Example: an office person on "Hourly" at 20 for 80 hours a month adds $1,600 a month here. Crew paid from jobs stay "Per job" (covered by the 20%).

Sheet Payments
A1: Payments (Square, both locations)
A2: Read from Square on 21 Oct 2026. Failed charges and a $0 entry are left out. Customer and job are my match by amount and date; check them. A job's Square fees are the rows with its customer and job date.
A4: Date | B4: Month | C4: Square location | D4: Business | E4: Type | F4: Amount ($) | G4: Refunded ($) | H4: Square fee ($) | I4: Money in ($) | J4: Money in after fee ($) | K4: Customer | L4: Job it paid for (job date) | M4: What it was
A5: 46265 | B5: =TEXT(A5,"yyyy-mm") | C5: Six Fold Colorado | D5: Sixfold | E5: Card | F5: 1 | G5: 0 | H5: 0 | I5: =F5-G5 | J5: =I5-H5 | K5: Test | M5: A $1 card charge: looks like a test.
A6: 46267 | B6: =TEXT(A6,"yyyy-mm") | C6: Six Fold Colorado | D6: Sixfold | E6: Check | F6: 1125 | G6: 0 | H6: 0 | I6: =F6-G6 | J6: =I6-H6 | M6: A check entered in Square. Which job? (question 7)
A7: 46281 | B7: =TEXT(A7,"yyyy-mm") | C7: Six Fold Colorado | D7: Sixfold | E7: Card | F7: 750 | G7: 0 | H7: 0 | I7: =F7-G7 | J7: =I7-H7 | K7: Kara R. | L7: 46282 | M7: Landscaping, first half. Square charged no fee on this one.
A8: 46283 | B8: =TEXT(A8,"yyyy-mm") | C8: Six Fold Colorado | D8: Sixfold | E8: Card | F8: 750 | G8: 0 | H8: 14.73 | I8: =F8-G8 | J8: =I8-H8 | K8: Kara R. | L8: 46282 | M8: Landscaping, second half
A9: 46301 | B9: =TEXT(A9,"yyyy-mm") | C9: Six Fold Colorado | D9: Sixfold | E9: Card | F9: 550 | G9: 0 | H9: 16.25 | I9: =F9-G9 | J9: =I9-H9 | K9: Kara R. | L9: 46307 | M9: Aeration, first half
A10: 46302 | B10: =TEXT(A10,"yyyy-mm") | C10: Six Fold Colorado | D10: Sixfold | E10: Card | F10: 200 | G10: 0 | H10: 6.1 | I10: =F10-G10 | J10: =I10-H10 | K10: Brian S. | L10: 46311 | M10: Aeration, first half ($200 still owed)
A11: 46311 | B11: =TEXT(A11,"yyyy-mm") | C11: Six Fold Colorado | D11: Sixfold | E11: Card | F11: 550 | G11: 0 | H11: 16.25 | I11: =F11-G11 | J11: =I11-H11 | K11: Kara R. | L11: 46307 | M11: Aeration, second half
A12: 46311 | B12: =TEXT(A12,"yyyy-mm") | C12: 365Aeration | D12: 365 | E12: Card | F12: 50 | G12: 0 | H12: 1.75 | I12: =F12-G12 | J12: =I12-H12 | K12: Kirk C. | L12: 46314 | M12: Deposit
A13: 46311 | B13: =TEXT(A13,"yyyy-mm") | C13: 365Aeration | D13: 365 | E13: Card | F13: 200 | G13: 0 | H13: 6.1 | I13: =F13-G13 | J13: =I13-H13 | K13: Russ K. | L13: 46311 | M13: Paid in full
A14: 46311 | B14: =TEXT(A14,"yyyy-mm") | C14: 365Aeration | D14: 365 | E14: Card | F14: 200 | G14: 0 | H14: 6.1 | I14: =F14-G14 | J14: =I14-H14 | K14: Eric V. | L14: 46311 | M14: Paid in full
A15: 46311 | B15: =TEXT(A15,"yyyy-mm") | C15: 365Aeration | D15: 365 | E15: Card | F15: 200 | G15: 25 | H15: 7.15 | I15: =F15-G15 | J15: =I15-H15 | K15: Carlos P. | L15: 46311 | M15: $200 with $25 refunded: his $175 price
A16: 46313 | B16: =TEXT(A16,"yyyy-mm") | C16: 365Aeration | D16: 365 | E16: Card | F16: 50 | G16: 0 | H16: 1.75 | I16: =F16-G16 | J16: =I16-H16 | K16: Sreenivas K. | L16: 46318 | M16: Deposit (job 23 Oct)
A17: 46314 | B17: =TEXT(A17,"yyyy-mm") | C17: 365Aeration | D17: 365 | E17: Card | F17: 249 | G17: 0 | H17: 8.87 | I17: =F17-G17 | J17: =I17-H17 | K17: Kirk C. | L17: 46314 | M17: Balance after the $50 deposit
A18: 46315 | B18: =TEXT(A18,"yyyy-mm") | C18: 365Aeration | D18: 365 | E18: Card | F18: 468 | G18: 0 | H18: 15.74 | I18: =F18-G18 | J18: =I18-H18 | K18: Randy C. | L18: 46315 | M18: Paid in full
... A20: 46316 | B20: =TEXT(A20,"yyyy-mm") | C20: 365Aeration | D20: 365 | E20: Card | F20: 350 | G20: 0 | H20: 11.85 | I20: =F20-G20 | J20: =I20-H20 | K20: Jeremy | L20: 46315 | M20: Paid in full at the $350 agreed
B21: =IF(A21="","",TEXT(A21,"yyyy-mm")) | I21: =IF(F21="","",N(F21)-N(G21)) | J21: =IF(F21="","",N(I21)-N(H21))
B22: =IF(A22="","",TEXT(A22,"yyyy-mm")) | I22: =IF(F22="","",N(F22)-N(G22)) | J22: =IF(F22="","",N(I22)-N(H22))
B23: =IF(A23="","",TEXT(A23,"yyyy-mm")) | I23: =IF(F23="","",N(F23)-N(G23)) | J23: =IF(F23="","",N(I23)-N(H23))
B24: =IF(A24="","",TEXT(A24,"yyyy-mm")) | I24: =IF(F24="","",N(F24)-N(G24)) | J24: =IF(F24="","",N(I24)-N(H24))
B25: =IF(A25="","",TEXT(A25,"yyyy-mm")) | I25: =IF(F25="","",N(F25)-N(G25)) | J25: =IF(F25="","",N(I25)-N(H25))
B26: =IF(A26="","",TEXT(A26,"yyyy-mm")) | I26: =IF(F26="","",N(F26)-N(G26)) | J26: =IF(F26="","",N(I26)-N(H26))
A27: Total | F27: =SUM(F5:F26) | G27: =SUM(G5:G26) | H27: =SUM(H5:H26) | I27: =SUM(I5:I26) | J27: =SUM(J5:J26)
A28: Square fee as a share of card money | H28: =IFERROR(SUMIFS(H5:H26,E5:E26,"Card")/SUMIFS(I5:I26,E5:E26,"Card"),0)

Sheet Variable per job
A1: Variable costs per job
A2: Seed, fertilizer, gas, Square fees and crew pay for each job, and what each job made. Inputs first; the jobs table is below.
A3: Aerator gas inputs are at the right of the table (columns AD to AF).
A4: Inputs | AD4: Aerator gas inputs
A5: Seed: price per bag ($) | D5: 128.89 | E5: SiteOne Englewood invoice 2026-07-24: 6 x 50 lb LESCO Tuf-Turf Seed Mixture, $773.34 with tax. | AD5: Aerator: fuel tank (gal) | AE5: 0.5 | AF5: Bobcat AE26-HON spec page (new.bobcat.com, read 2026-10-21): 0.5 gal. Honda lists the GX120 tank as 2.0 L.
A6: Seed: pounds per bag | D6: 50 | E6: Same invoice. | AD6: Aerator: fuel burn (gal per hour) | AE6: 0.2642 | AF6: Honda GX120: 1.0 L/h at rated power (3,600 rpm), as republished by Honda dealers; not found on Honda’s own site. Full throttle: the most it burns.
A7: Seed: lb per 1,000 sq ft when not recorded | D7: 3 | E7: The app's middle seeding rate (Bryce's 2 to 4 lb range; CSU says 3 to 4 after aeration). | AD7: Aerator: coverage (sq ft per hour) | AE7: 40400 | AF7: Bobcat AE26 maximum productivity at 3.5 mph, 26.5 in wide. No turns, trees or overlap: real jobs are slower.
A8: Fertilizer: price per bag ($) | D8: 40 | E8: Matthew, 21 Oct 2026: $40 for a 50 lb bag. | AD8: Aerator: real pace (share of Bobcat’s top rate) | AE8: 1 | AF8: Yours to set. 100% = Bobcat’s figure (the least gas). Lower it once fill-ups show what a tank really covers.
A9: Fertilizer: pounds per bag | D9: 50 | E9: Label. | AD9: Aerator: sq ft per tank | AE9: =AE5/AE6*AE7*AE8 | AF9: Worked out: tank / burn x coverage x pace.
A10: Fertilizer: sq ft one bag covers | D10: 12000 | E10: Label: a 50 lb bag covers about 12,000 sq ft.
A11: Gas: price per gallon ($) | D11: 4.244 | E11: EIA weekly retail, Denver regular, week of 2026-10-19 (what the app uses for quotes).
A12: Truck: miles per gallon | D12: 18 | E12: The app's setting (Matthew, 2026-10-15).
A13: Road miles per straight-line mile | D13: 1.3 | E13: The app's setting: roads are about 30% longer than a straight line.
A14: Employee cost: share of each job's price | D14: 0.2 | E14: Matthew, 21 Oct 2026: a 20% employee cost on every job.
A15: Date | B15: Customer | C15: Business | D15: Service | E15: Status | F15: Crew | G15: Price ($) | H15: Collected ($) | I15: Still owed ($) | J15: Lawn sq ft | K15: Lawn size from | L15: Seed lb recorded | M15: Seed lb used | N15: Seed ($) | O15: Fert lb recorded | P15: Fert lb used | Q15: Fert ($) | R15: Miles one way (straight line) | S15: Gas ($) | T15: Gas override ($) | U15: Square fees ($) | V15: Other materials ($) | W15: Employee cost override ($) | X15: Employee cost, 20% ($) | Y15: Job cost ($) | Z15: Job profit ($) | AA15: Margin | AB15: Month | AC15: Aerator gas ($)
A16: 46282 | B16: Kara R. | C16: Sixfold | D16: Landscaping | E16: Done | G16: 1500 | H16: 1500 | I16: =G16-H16 | K16: No lawn: landscaping | L16: 0 | M16: =IF(L16<>"",N(L16),N(J16)/1000*$D$7) | N16: =M16*($D$5/$D$6) | O16: 0 | P16: =IF(O16<>"",N(O16),N(J16)*($D$9/$D$10)) | Q16: =P16*($D$8/$D$9) | S16: =IF(T16<>"",N(T16),N(R16)*$D$13*2/$D$12*$D$11) | U16: =SUMIFS(Payments!$H$5:$H$26,Payments!$K$5:$K$26,B16,Payments!$L$5:$L$26,A16) | X16: =IF(W16<>"",N(W16),G16*$D$14) | Y16: =N16+Q16+S16+U16+N(V16)+X16+N(AC16) | Z16: =G16-Y16 | AA16: =IF(G16=0,0,Z16/G16) | AB16: =TEXT(A16,"yyyy-mm") | AC16: =N(J16)/($AE$7*$AE$8)*$AE$6*$D$11
A17: 46307 | B17: Kara R. | C17: Sixfold | D17: Aeration | E17: Done | G17: 1100 | H17: 1100 | I17: =G17-H17 | K17: Not recorded | M17: =IF(L17<>"",N(L17),N(J17)/1000*$D$7) | N17: =M17*($D$5/$D$6) | P17: =IF(O17<>"",N(O17),N(J17)*($D$9/$D$10)) | Q17: =P17*($D$8/$D$9) | S17: =IF(T17<>"",N(T17),N(R17)*$D$13*2/$D$12*$D$11) | U17: =SUMIFS(Payments!$H$5:$H$26,Payments!$K$5:$K$26,B17,Payments!$L$5:$L$26,A17) | X17: =IF(W17<>"",N(W17),G17*$D$14) | Y17: =N17+Q17+S17+U17+N(V17)+X17+N(AC17) | Z17: =G17-Y17 | AA17: =IF(G17=0,0,Z17/G17) | AB17: =TEXT(A17,"yyyy-mm") | AC17: =N(J17)/($AE$7*$AE$8)*$AE$6*$D$11
A18: 46311 | B18: Brian S. | C18: Sixfold | D18: Aeration | E18: Done | F18: Brad McPherson | G18: 400 | H18: 200 | I18: =G18-H18 | K18: Aerial: trees cover it | M18: =IF(L18<>"",N(L18),N(J18)/1000*$D$7) | N18: =M18*($D$5/$D$6) | P18: =IF(O18<>"",N(O18),N(J18)*($D$9/$D$10)) | Q18: =P18*($D$8/$D$9) | R18: 17.23 | S18: =IF(T18<>"",N(T18),N(R18)*$D$13*2/$D$12*$D$11) | U18: =SUMIFS(Payments!$H$5:$H$26,Payments!$K$5:$K$26,B18,Payments!$L$5:$L$26,A18) | X18: =IF(W18<>"",N(W18),G18*$D$14) | Y18: =N18+Q18+S18+U18+N(V18)+X18+N(AC18) | Z18: =G18-Y18 | AA18: =IF(G18=0,0,Z18/G18) | AB18: =TEXT(A18,"yyyy-mm") | AC18: =N(J18)/($AE$7*$AE$8)*$AE$6*$D$11
A19: 46311 | B19: Russ K. | C19: 365 | D19: Aeration + seed | E19: Done | F19: Brad McPherson | G19: 200 | H19: 200 | I19: =G19-H19 | J19: 800 | K19: Aerial estimate | M19: =IF(L19<>"",N(L19),N(J19)/1000*$D$7) | N19: =M19*($D$5/$D$6) | P19: =IF(O19<>"",N(O19),N(J19)*($D$9/$D$10)) | Q19: =P19*($D$8/$D$9) | R19: 8.91 | S19: =IF(T19<>"",N(T19),N(R19)*$D$13*2/$D$12*$D$11) | U19: =SUMIFS(Payments!$H$5:$H$26,Payments!$K$5:$K$26,B19,Payments!$L$5:$L$26,A19) | X19: =IF(W19<>"",N(W19),G19*$D$14) | Y19: =N19+Q19+S19+U19+N(V19)+X19+N(AC19) | Z19: =G19-Y19 | AA19: =IF(G19=0,0,Z19/G19) | AB19: =TEXT(A19,"yyyy-mm") | AC19: =N(J19)/($AE$7*$AE$8)*$AE$6*$D$11
A20: 46311 | B20: Eric V. | C20: 365 | D20: Aeration + seed | E20: Done | F20: Brad McPherson | G20: 200 | H20: 200 | I20: =G20-H20 | J20: 700 | K20: Aerial estimate | M20: =IF(L20<>"",N(L20),N(J20)/1000*$D$7) | N20: =M20*($D$5/$D$6) | P20: =IF(O20<>"",N(O20),N(J20)*($D$9/$D$10)) | Q20: =P20*($D$8/$D$9) | R20: 8.92 | S20: =IF(T20<>"",N(T20),N(R20)*$D$13*2/$D$12*$D$11) | U20: =SUMIFS(Payments!$H$5:$H$26,Payments!$K$5:$K$26,B20,Payments!$L$5:$L$26,A20) | X20: =IF(W20<>"",N(W20),G20*$D$14) | Y20: =N20+Q20+S20+U20+N(V20)+X20+N(AC20) | Z20: =G20-Y20 | AA20: =IF(G20=0,0,Z20/G20) | AB20: =TEXT(A20,"yyyy-mm") | AC20: =N(J20)/($AE$7*$AE$8)*$AE$6*$D$11
A21: 46311 | B21: Carlos P. | C21: 365 | D21: Aeration + seed | E21: Done | F21: Brandon Long | G21: 175 | H21: 175 | I21: =G21-H21 | J21: 1300 | K21: Jen's quote | L21: 2.6 | M21: =IF(L21<>"",N(L21),N(J21)/1000*$D$7) | N21: =M21*($D$5/$D$6) | O21: 5.4 | P21: =IF(O21<>"",N(O21),N(J21)*($D$9/$D$10)) | Q21: =P21*($D$8/$D$9) | S21: =IF(T21<>"",N(T21),N(R21)*$D$13*2/$D$12*$D$11) | U21: =SUMIFS(Payments!$H$5:$H$26,Payments!$K$5:$K$26,B21,Payments!$L$5:$L$26,A21) | X21: =IF(W21<>"",N(W21),G21*$D$14) | Y21: =N21+Q21+S21+U21+N(V21)+X21+N(AC21) | Z21: =G21-Y21 | AA21: =IF(G21=0,0,Z21/G21) | AB21: =TEXT(A21,"yyyy-mm") | AC21: =N(J21)/($AE$7*$AE$8)*$AE$6*$D$11
A22: 46314 | B22: Kirk C. | C22: 365 | D22: Aeration + seed | E22: Done | F22: Brad McPherson | G22: 299 | H22: 299 | I22: =G22-H22 | J22: 3600 | K22: Aerial estimate | M22: =IF(L22<>"",N(L22),N(J22)/1000*$D$7) | N22: =M22*($D$5/$D$6) | P22: =IF(O22<>"",N(O22),N(J22)*($D$9/$D$10)) | Q22: =P22*($D$8/$D$9) | R22: 16.04 | S22: =IF(T22<>"",N(T22),N(R22)*$D$13*2/$D$12*$D$11) | U22: =SUMIFS(Payments!$H$5:$H$26,Payments!$K$5:$K$26,B22,Payments!$L$5:$L$26,A22) | X22: =IF(W22<>"",N(W22),G22*$D$14) | Y22: =N22+Q22+S22+U22+N(V22)+X22+N(AC22) | Z22: =G22-Y22 | AA22: =IF(G22=0,0,Z22/G22) | AB22: =TEXT(A22,"yyyy-mm") | AC22: =N(J22)/($AE$7*$AE$8)*$AE$6*$D$11
A23: 46315 | B23: Jeremy | C23: 365 | D23: Aeration + seed | E23: Done | F23: Brad McPherson | G23: 350 | H23: 350 | I23: =G23-H23 | J23: 1000 | K23: Jen's quote | L23: 3 | M23: =IF(L23<>"",N(L23),N(J23)/1000*$D$7) | N23: =M23*($D$5/$D$6) | O23: 4.2 | P23: =IF(O23<>"",N(O23),N(J23)*($D$9/$D$10)) | Q23: =P23*($D$8/$D$9) | R23: 12.78 | S23: =IF(T23<>"",N(T23),N(R23)*$D$13*2/$D$12*$D$11) | U23: =SUMIFS(Payments!$H$5:$H$26,Payments!$K$5:$K$26,B23,Payments!$L$5:$L$26,A23) | X23: =IF(W23<>"",N(W23),G23*$D$14) | Y23: =N23+Q23+S23+U23+N(V23)+X23+N(AC23) | Z23: =G23-Y23 | AA23: =IF(G23=0,0,Z23/G23) | AB23: =TEXT(A23,"yyyy-mm") | AC23: =N(J23)/($AE$7*$AE$8)*$AE$6*$D$11
A24: 46315 | B24: Randy C. | C24: 365 | D24: Aeration + seed | E24: Done | F24: Brad McPherson | G24: 468 | H24: 468 | I24: =G24-H24 | J24: 2200 | K24: Jen's quote | L24: 7.6 | M24: =IF(L24<>"",N(L24),N(J24)/1000*$D$7) | N24: =M24*($D$5/$D$6) | O24: 9.2 | P24: =IF(O24<>"",N(O24),N(J24)*($D$9/$D$10)) | Q24: =P24*($D$8/$D$9) | R24: 13.07 | S24: =IF(T24<>"",N(T24),N(R24)*$D$13*2/$D$12*$D$11) | U24: =SUMIFS(Payments!$H$5:$H$26,Payments!$K$5:$K$26,B24,Payments!$L$5:$L$26,A24) | X24: =IF(W24<>"",N(W24),G24*$D$14) | Y24: =N24+Q24+S24+U24+N(V24)+X24+N(AC24) | Z24: =G24-Y24 | AA24: =IF(G24=0,0,Z24/G24) | AB24: =TEXT(A24,"yyyy-mm") | AC24: =N(J24)/($AE$7*$AE$8)*$AE$6*$D$11
A25: 46318 | B25: Sreenivas K. | C25: 365 | D25: Aeration + seed | E25: Booked | F25: Brad McPherson | G25: 339 | H25: 50 | I25: =G25-H25 | J25: 200 | K25: Aerial: looks too small, check | M25: =IF(L25<>"",N(L25),N(J25)/1000*$D$7) | N25: =M25*($D$5/$D$6) | P25: =IF(O25<>"",N(O25),N(J25)*($D$9/$D$10)) | Q25: =P25*($D$8/$D$9) | R25: 9.24 | S25: =IF(T25<>"",N(T25),N(R25)*$D$13*2/$D$12*$D$11) | U25: =SUMIFS(Payments!$H$5:$H$26,Payments!$K$5:$K$26,B25,Payments!$L$5:$L$26,A25) | X25: =IF(W25<>"",N(W25),G25*$D$14) | Y25: =N25+Q25+S25+U25+N(V25)+X25+N(AC25) | Z25: =G25-Y25 | AA25: =IF(G25=0,0,Z25/G25) | AB25: =TEXT(A25,"yyyy-mm") | AC25: =N(J25)/($AE$7*$AE$8)*$AE$6*$D$11
A26: 46325 | B26: Joseph B. | C26: 365 | D26: Aeration + seed | E26: Booked | F26: Brad McPherson | G26: 814 | H26: 200 | I26: =G26-H26 | K26: Not recorded | M26: =IF(L26<>"",N(L26),N(J26)/1000*$D$7) | N26: =M26*($D$5/$D$6) | P26: =IF(O26<>"",N(O26),N(J26)*($D$9/$D$10)) | Q26: =P26*($D$8/$D$9) | S26: =IF(T26<>"",N(T26),N(R26)*$D$13*2/$D$12*$D$11) | U26: =SUMIFS(Payments!$H$5:$H$26,Payments!$K$5:$K$26,B26,Payments!$L$5:$L$26,A26) | X26: =IF(W26<>"",N(W26),G26*$D$14) | Y26: =N26+Q26+S26+U26+N(V26)+X26+N(AC26) | Z26: =G26-Y26 | AA26: =IF(G26=0,0,Z26/G26) | AB26: =TEXT(A26,"yyyy-mm") | AC26: =N(J26)/($AE$7*$AE$8)*$AE$6*$D$11
I27: =IF(G27="","",G27-N(H27)) | M27: =IF(G27="","",IF(L27<>"",N(L27),N(J27)/1000*$D$7)) | N27: =IF(G27="","",N(M27)*($D$5/$D$6)) | P27: =IF(G27="","",IF(O27<>"",N(O27),N(J27)*($D$9/$D$10))) | Q27: =IF(G27="","",N(P27)*($D$8/$D$9)) | S27: =IF(G27="","",IF(T27<>"",N(T27),N(R27)*$D$13*2/$D$12*$D$11)) | U27: =IF(G27="","",SUMIFS(Payments!$H$5:$H$26,Payments!$K$5:$K$26,B27,Payments!$L$5:$L$26,A27)) | X27: =IF(G27="","",IF(W27<>"",N(W27),G27*$D$14)) | Y27: =IF(G27="","",N(N27)+N(Q27)+N(S27)+N(U27)+N(V27)+N(X27)+N(AC27)) | Z27: =IF(G27="","",G27-N(Y27)) | AA27: =IF(N(G27)=0,"",N(Z27)/G27) | AB27: =IF(A27="","",TEXT(A27,"yyyy-mm")) | AC27: =IF(G27="","",N(J27)/($AE$7*$AE$8)*$AE$6*$D$11)
I28: =IF(G28="","",G28-N(H28)) | M28: =IF(G28="","",IF(L28<>"",N(L28),N(J28)/1000*$D$7)) | N28: =IF(G28="","",N(M28)*($D$5/$D$6)) | P28: =IF(G28="","",IF(O28<>"",N(O28),N(J28)*($D$9/$D$10))) | Q28: =IF(G28="","",N(P28)*($D$8/$D$9)) | S28: =IF(G28="","",IF(T28<>"",N(T28),N(R28)*$D$13*2/$D$12*$D$11)) | U28: =IF(G28="","",SUMIFS(Payments!$H$5:$H$26,Payments!$K$5:$K$26,B28,Payments!$L$5:$L$26,A28)) | X28: =IF(G28="","",IF(W28<>"",N(W28),G28*$D$14)) | Y28: =IF(G28="","",N(N28)+N(Q28)+N(S28)+N(U28)+N(V28)+N(X28)+N(AC28)) | Z28: =IF(G28="","",G28-N(Y28)) | AA28: =IF(N(G28)=0,"",N(Z28)/G28) | AB28: =IF(A28="","",TEXT(A28,"yyyy-mm")) | AC28: =IF(G28="","",N(J28)/($AE$7*$AE$8)*$AE$6*$D$11)
I29: =IF(G29="","",G29-N(H29)) | M29: =IF(G29="","",IF(L29<>"",N(L29),N(J29)/1000*$D$7)) | N29: =IF(G29="","",N(M29)*($D$5/$D$6)) | P29: =IF(G29="","",IF(O29<>"",N(O29),N(J29)*($D$9/$D$10))) | Q29: =IF(G29="","",N(P29)*($D$8/$D$9)) | S29: =IF(G29="","",IF(T29<>"",N(T29),N(R29)*$D$13*2/$D$12*$D$11)) | U29: =IF(G29="","",SUMIFS(Payments!$H$5:$H$26,Payments!$K$5:$K$26,B29,Payments!$L$5:$L$26,A29)) | X29: =IF(G29="","",IF(W29<>"",N(W29),G29*$D$14)) | Y29: =IF(G29="","",N(N29)+N(Q29)+N(S29)+N(U29)+N(V29)+N(X29)+N(AC29)) | Z29: =IF(G29="","",G29-N(Y29)) | AA29: =IF(N(G29)=0,"",N(Z29)/G29) | AB29: =IF(A29="","",TEXT(A29,"yyyy-mm")) | AC29: =IF(G29="","",N(J29)/($AE$7*$AE$8)*$AE$6*$D$11)
I30: =IF(G30="","",G30-N(H30)) | M30: =IF(G30="","",IF(L30<>"",N(L30),N(J30)/1000*$D$7)) | N30: =IF(G30="","",N(M30)*($D$5/$D$6)) | P30: =IF(G30="","",IF(O30<>"",N(O30),N(J30)*($D$9/$D$10))) | Q30: =IF(G30="","",N(P30)*($D$8/$D$9)) | S30: =IF(G30="","",IF(T30<>"",N(T30),N(R30)*$D$13*2/$D$12*$D$11)) | U30: =IF(G30="","",SUMIFS(Payments!$H$5:$H$26,Payments!$K$5:$K$26,B30,Payments!$L$5:$L$26,A30)) | X30: =IF(G30="","",IF(W30<>"",N(W30),G30*$D$14)) | Y30: =IF(G30="","",N(N30)+N(Q30)+N(S30)+N(U30)+N(V30)+N(X30)+N(AC30)) | Z30: =IF(G30="","",G30-N(Y30)) | AA30: =IF(N(G30)=0,"",N(Z30)/G30) | AB30: =IF(A30="","",TEXT(A30,"yyyy-mm")) | AC30: =IF(G30="","",N(J30)/($AE$7*$AE$8)*$AE$6*$D$11)
I31: =IF(G31="","",G31-N(H31)) | M31: =IF(G31="","",IF(L31<>"",N(L31),N(J31)/1000*$D$7)) | N31: =IF(G31="","",N(M31)*($D$5/$D$6)) | P31: =IF(G31="","",IF(O31<>"",N(O31),N(J31)*($D$9/$D$10))) | Q31: =IF(G31="","",N(P31)*($D$8/$D$9)) | S31: =IF(G31="","",IF(T31<>"",N(T31),N(R31)*$D$13*2/$D$12*$D$11)) | U31: =IF(G31="","",SUMIFS(Payments!$H$5:$H$26,Payments!$K$5:$K$26,B31,Payments!$L$5:$L$26,A31)) | X31: =IF(G31="","",IF(W31<>"",N(W31),G31*$D$14)) | Y31: =IF(G31="","",N(N31)+N(Q31)+N(S31)+N(U31)+N(V31)+N(X31)+N(AC31)) | Z31: =IF(G31="","",G31-N(Y31)) | AA31: =IF(N(G31)=0,"",N(Z31)/G31) | AB31: =IF(A31="","",TEXT(A31,"yyyy-mm")) | AC31: =IF(G31="","",N(J31)/($AE$7*$AE$8)*$AE$6*$D$11)
I32: =IF(G32="","",G32-N(H32)) | M32: =IF(G32="","",IF(L32<>"",N(L32),N(J32)/1000*$D$7)) | N32: =IF(G32="","",N(M32)*($D$5/$D$6)) | P32: =IF(G32="","",IF(O32<>"",N(O32),N(J32)*($D$9/$D$10))) | Q32: =IF(G32="","",N(P32)*($D$8/$D$9)) | S32: =IF(G32="","",IF(T32<>"",N(T32),N(R32)*$D$13*2/$D$12*$D$11)) | U32: =IF(G32="","",SUMIFS(Payments!$H$5:$H$26,Payments!$K$5:$K$26,B32,Payments!$L$5:$L$26,A32)) | X32: =IF(G32="","",IF(W32<>"",N(W32),G32*$D$14)) | Y32: =IF(G32="","",N(N32)+N(Q32)+N(S32)+N(U32)+N(V32)+N(X32)+N(AC32)) | Z32: =IF(G32="","",G32-N(Y32)) | AA32: =IF(N(G32)=0,"",N(Z32)/G32) | AB32: =IF(A32="","",TEXT(A32,"yyyy-mm")) | AC32: =IF(G32="","",N(J32)/($AE$7*$AE$8)*$AE$6*$D$11)
I33: =IF(G33="","",G33-N(H33)) | M33: =IF(G33="","",IF(L33<>"",N(L33),N(J33)/1000*$D$7)) | N33: =IF(G33="","",N(M33)*($D$5/$D$6)) | P33: =IF(G33="","",IF(O33<>"",N(O33),N(J33)*($D$9/$D$10))) | Q33: =IF(G33="","",N(P33)*($D$8/$D$9)) | S33: =IF(G33="","",IF(T33<>"",N(T33),N(R33)*$D$13*2/$D$12*$D$11)) | U33: =IF(G33="","",SUMIFS(Payments!$H$5:$H$26,Payments!$K$5:$K$26,B33,Payments!$L$5:$L$26,A33)) | X33: =IF(G33="","",IF(W33<>"",N(W33),G33*$D$14)) | Y33: =IF(G33="","",N(N33)+N(Q33)+N(S33)+N(U33)+N(V33)+N(X33)+N(AC33)) | Z33: =IF(G33="","",G33-N(Y33)) | AA33: =IF(N(G33)=0,"",N(Z33)/G33) | AB33: =IF(A33="","",TEXT(A33,"yyyy-mm")) | AC33: =IF(G33="","",N(J33)/($AE$7*$AE$8)*$AE$6*$D$11)
I34: =IF(G34="","",G34-N(H34)) | M34: =IF(G34="","",IF(L34<>"",N(L34),N(J34)/1000*$D$7)) | N34: =IF(G34="","",N(M34)*($D$5/$D$6)) | P34: =IF(G34="","",IF(O34<>"",N(O34),N(J34)*($D$9/$D$10))) | Q34: =IF(G34="","",N(P34)*($D$8/$D$9)) | S34: =IF(G34="","",IF(T34<>"",N(T34),N(R34)*$D$13*2/$D$12*$D$11)) | U34: =IF(G34="","",SUMIFS(Payments!$H$5:$H$26,Payments!$K$5:$K$26,B34,Payments!$L$5:$L$26,A34)) | X34: =IF(G34="","",IF(W34<>"",N(W34),G34*$D$14)) | Y34: =IF(G34="","",N(N34)+N(Q34)+N(S34)+N(U34)+N(V34)+N(X34)+N(AC34)) | Z34: =IF(G34="","",G34-N(Y34)) | AA34: =IF(N(G34)=0,"",N(Z34)/G34) | AB34: =IF(A34="","",TEXT(A34,"yyyy-mm")) | AC34: =IF(G34="","",N(J34)/($AE$7*$AE$8)*$AE$6*$D$11)
A35: Total | G35: =SUM(G16:G34) | H35: =SUM(H16:H34) | I35: =SUM(I16:I34) | M35: =SUM(M16:M34) | N35: =SUM(N16:N34) | P35: =SUM(P16:P34) | Q35: =SUM(Q16:Q34) | S35: =SUM(S16:S34) | U35: =SUM(U16:U34) | V35: =SUM(V16:V34) | X35: =SUM(X16:X34) | Y35: =SUM(Y16:Y34) | Z35: =SUM(Z16:Z34) | AA35: =IF(G35=0,0,Z35/G35)
A37: Square fees come from the Payments tab by customer. Crew pay comes from the Employees tab unless you type an override. Collected and price are from the app. Seed and fertilizer lb: Jen's quote where recorded, otherwise the lawn size x the rates above. Aerator gas: lawn sq ft over the Bobcat’s coverage, times its fuel per hour and the gas price (inputs at AD5:AE9); a job with no lawn size has none.
